Traceback (most recent call last):
  File "/home/aymeric/anaconda3/envs/analyse_tweets/lib/python3.9/site-packages/jupyter_cache/executors/utils.py", line 51, in single_nb_execution
    executenb(
  File "/home/aymeric/anaconda3/envs/analyse_tweets/lib/python3.9/site-packages/nbclient/client.py", line 1093, in execute
    return NotebookClient(nb=nb, resources=resources, km=km, **kwargs).execute()
  File "/home/aymeric/anaconda3/envs/analyse_tweets/lib/python3.9/site-packages/nbclient/util.py", line 84, in wrapped
    return just_run(coro(*args, **kwargs))
  File "/home/aymeric/anaconda3/envs/analyse_tweets/lib/python3.9/site-packages/nbclient/util.py", line 62, in just_run
    return loop.run_until_complete(coro)
  File "/home/aymeric/anaconda3/envs/analyse_tweets/lib/python3.9/asyncio/base_events.py", line 642, in run_until_complete
    return future.result()
  File "/home/aymeric/anaconda3/envs/analyse_tweets/lib/python3.9/site-packages/nbclient/client.py", line 559, in async_execute
    await self.async_execute_cell(
  File "/home/aymeric/anaconda3/envs/analyse_tweets/lib/python3.9/site-packages/nbclient/client.py", line 854, in async_execute_cell
    self._check_raise_for_error(cell, exec_reply)
  File "/home/aymeric/anaconda3/envs/analyse_tweets/lib/python3.9/site-packages/nbclient/client.py", line 756, in _check_raise_for_error
    raise CellExecutionError.from_cell_and_msg(cell, exec_reply_content)
nbclient.exceptions.CellExecutionError: An error occurred while executing the following cell:
------------------
df1 = df0[['query', 'id', 'timestamp_utc', 'local_time',
           'user_screen_name', 'text',  'user_location',  'user_id', 'user_name',
           'ROS1', 'ALK', 'EXON', 'EGFR', 'KRAS', 'NTRK',
           'BRAF', 'MET', 'RET', 'HER2', 'date', "nb_of_biomarker"]]
------------------

[0;31m---------------------------------------------------------------------------[0m
[0;31mKeyError[0m                                  Traceback (most recent call last)
[0;32m/tmp/ipykernel_6750/2417038728.py[0m in [0;36m<module>[0;34m[0m
[0;32m----> 1[0;31m df1 = df0[['query', 'id', 'timestamp_utc', 'local_time',
[0m[1;32m      2[0m            [0;34m'user_screen_name'[0m[0;34m,[0m [0;34m'text'[0m[0;34m,[0m  [0;34m'user_location'[0m[0;34m,[0m  [0;34m'user_id'[0m[0;34m,[0m [0;34m'user_name'[0m[0;34m,[0m[0;34m[0m[0;34m[0m[0m
[1;32m      3[0m            [0;34m'ROS1'[0m[0;34m,[0m [0;34m'ALK'[0m[0;34m,[0m [0;34m'EXON'[0m[0;34m,[0m [0;34m'EGFR'[0m[0;34m,[0m [0;34m'KRAS'[0m[0;34m,[0m [0;34m'NTRK'[0m[0;34m,[0m[0;34m[0m[0;34m[0m[0m
[1;32m      4[0m            'BRAF', 'MET', 'RET', 'HER2', 'date', "nb_of_biomarker"]]

[0;32m~/anaconda3/envs/analyse_tweets/lib/python3.9/site-packages/pandas/core/frame.py[0m in [0;36m__getitem__[0;34m(self, key)[0m
[1;32m   3462[0m             [0;32mif[0m [0mis_iterator[0m[0;34m([0m[0mkey[0m[0;34m)[0m[0;34m:[0m[0;34m[0m[0;34m[0m[0m
[1;32m   3463[0m                 [0mkey[0m [0;34m=[0m [0mlist[0m[0;34m([0m[0mkey[0m[0;34m)[0m[0;34m[0m[0;34m[0m[0m
[0;32m-> 3464[0;31m             [0mindexer[0m [0;34m=[0m [0mself[0m[0;34m.[0m[0mloc[0m[0;34m.[0m[0m_get_listlike_indexer[0m[0;34m([0m[0mkey[0m[0;34m,[0m [0maxis[0m[0;34m=[0m[0;36m1[0m[0;34m)[0m[0;34m[[0m[0;36m1[0m[0;34m][0m[0;34m[0m[0;34m[0m[0m
[0m[1;32m   3465[0m [0;34m[0m[0m
[1;32m   3466[0m         [0;31m# take() does not accept boolean indexers[0m[0;34m[0m[0;34m[0m[0m

[0;32m~/anaconda3/envs/analyse_tweets/lib/python3.9/site-packages/pandas/core/indexing.py[0m in [0;36m_get_listlike_indexer[0;34m(self, key, axis)[0m
[1;32m   1312[0m             [0mkeyarr[0m[0;34m,[0m [0mindexer[0m[0;34m,[0m [0mnew_indexer[0m [0;34m=[0m [0max[0m[0;34m.[0m[0m_reindex_non_unique[0m[0;34m([0m[0mkeyarr[0m[0;34m)[0m[0;34m[0m[0;34m[0m[0m
[1;32m   1313[0m [0;34m[0m[0m
[0;32m-> 1314[0;31m         [0mself[0m[0;34m.[0m[0m_validate_read_indexer[0m[0;34m([0m[0mkeyarr[0m[0;34m,[0m [0mindexer[0m[0;34m,[0m [0maxis[0m[0;34m)[0m[0;34m[0m[0;34m[0m[0m
[0m[1;32m   1315[0m [0;34m[0m[0m
[1;32m   1316[0m         if needs_i8_conversion(ax.dtype) or isinstance(

[0;32m~/anaconda3/envs/analyse_tweets/lib/python3.9/site-packages/pandas/core/indexing.py[0m in [0;36m_validate_read_indexer[0;34m(self, key, indexer, axis)[0m
[1;32m   1375[0m [0;34m[0m[0m
[1;32m   1376[0m             [0mnot_found[0m [0;34m=[0m [0mlist[0m[0;34m([0m[0mensure_index[0m[0;34m([0m[0mkey[0m[0;34m)[0m[0;34m[[0m[0mmissing_mask[0m[0;34m.[0m[0mnonzero[0m[0;34m([0m[0;34m)[0m[0;34m[[0m[0;36m0[0m[0;34m][0m[0;34m][0m[0;34m.[0m[0munique[0m[0;34m([0m[0;34m)[0m[0;34m)[0m[0;34m[0m[0;34m[0m[0m
[0;32m-> 1377[0;31m             [0;32mraise[0m [0mKeyError[0m[0;34m([0m[0;34mf"{not_found} not in index"[0m[0;34m)[0m[0;34m[0m[0;34m[0m[0m
[0m[1;32m   1378[0m [0;34m[0m[0m
[1;32m   1379[0m [0;34m[0m[0m

[0;31mKeyError[0m: "['nb_of_biomarker'] not in index"
KeyError: "['nb_of_biomarker'] not in index"

