Traceback (most recent call last):
  File "/home/aymeric/anaconda3/envs/analyse_tweets/lib/python3.9/site-packages/jupyter_cache/executors/utils.py", line 51, in single_nb_execution
    executenb(
  File "/home/aymeric/anaconda3/envs/analyse_tweets/lib/python3.9/site-packages/nbclient/client.py", line 1093, in execute
    return NotebookClient(nb=nb, resources=resources, km=km, **kwargs).execute()
  File "/home/aymeric/anaconda3/envs/analyse_tweets/lib/python3.9/site-packages/nbclient/util.py", line 84, in wrapped
    return just_run(coro(*args, **kwargs))
  File "/home/aymeric/anaconda3/envs/analyse_tweets/lib/python3.9/site-packages/nbclient/util.py", line 62, in just_run
    return loop.run_until_complete(coro)
  File "/home/aymeric/anaconda3/envs/analyse_tweets/lib/python3.9/asyncio/base_events.py", line 642, in run_until_complete
    return future.result()
  File "/home/aymeric/anaconda3/envs/analyse_tweets/lib/python3.9/site-packages/nbclient/client.py", line 559, in async_execute
    await self.async_execute_cell(
  File "/home/aymeric/anaconda3/envs/analyse_tweets/lib/python3.9/site-packages/nbclient/client.py", line 854, in async_execute_cell
    self._check_raise_for_error(cell, exec_reply)
  File "/home/aymeric/anaconda3/envs/analyse_tweets/lib/python3.9/site-packages/nbclient/client.py", line 756, in _check_raise_for_error
    raise CellExecutionError.from_cell_and_msg(cell, exec_reply_content)
nbclient.exceptions.CellExecutionError: An error occurred while executing the following cell:
------------------
df0 = df0[['query', 'id', 'timestamp_utc', 'local_time',
           'user_screen_name', 'text',  'user_location',  'user_id', 'user_name',
           'ROS1', 'ALK', 'EXON', 'EGFR', 'KRAS', 'NTRK',
           'BRAF', 'MET', 'RET', 'HER2', 'date']]
------------------

[0;31m---------------------------------------------------------------------------[0m
[0;31mNameError[0m                                 Traceback (most recent call last)
[0;32m/tmp/ipykernel_9725/3612863376.py[0m in [0;36m<module>[0;34m[0m
[0;32m----> 1[0;31m df0 = df0[['query', 'id', 'timestamp_utc', 'local_time',
[0m[1;32m      2[0m            [0;34m'user_screen_name'[0m[0;34m,[0m [0;34m'text'[0m[0;34m,[0m  [0;34m'user_location'[0m[0;34m,[0m  [0;34m'user_id'[0m[0;34m,[0m [0;34m'user_name'[0m[0;34m,[0m[0;34m[0m[0;34m[0m[0m
[1;32m      3[0m            [0;34m'ROS1'[0m[0;34m,[0m [0;34m'ALK'[0m[0;34m,[0m [0;34m'EXON'[0m[0;34m,[0m [0;34m'EGFR'[0m[0;34m,[0m [0;34m'KRAS'[0m[0;34m,[0m [0;34m'NTRK'[0m[0;34m,[0m[0;34m[0m[0;34m[0m[0m
[1;32m      4[0m            'BRAF', 'MET', 'RET', 'HER2', 'date']]

[0;31mNameError[0m: name 'df0' is not defined
NameError: name 'df0' is not defined

